[ERROR][2018-06-29 17:46:47,405][Thread-1:12416][task_id:django.request][exception.py:135][Internal Server Error: /]
Traceback (most recent call last):
  File "D:\Python27\lib\site-packages\django\core\handlers\exception.py", line 41, in inner
    response = get_response(request)
  File "D:\Python27\lib\site-packages\django\core\handlers\base.py", line 187, in _get_response
    response = self.process_exception_by_middleware(e, request)
  File "D:\Python27\lib\site-packages\django\core\handlers\base.py", line 185, in _get_response
    response = wrapped_callback(request, *callback_args, **callback_kwargs)
  File "D:\MyPythonProject\MSS\StreamSystem\class_based_views.py", line 29, in index
    return render(request, 'index.html')
  File "D:\Python27\lib\site-packages\django\shortcuts.py", line 30, in render
    content = loader.render_to_string(template_name, context, request, using=using)
  File "D:\Python27\lib\site-packages\django\template\loader.py", line 67, in render_to_string
    template = get_template(template_name, using=using)
  File "D:\Python27\lib\site-packages\django\template\loader.py", line 25, in get_template
    raise TemplateDoesNotExist(template_name, chain=chain)
TemplateDoesNotExist: index.html
[ERROR][2018-06-29 17:54:09,252][Thread-5:8468][task_id:django.request][exception.py:135][Internal Server Error: /stream/add/]
Traceback (most recent call last):
  File "D:\Python27\lib\site-packages\django\core\handlers\exception.py", line 41, in inner
    response = get_response(request)
  File "D:\Python27\lib\site-packages\django\core\handlers\base.py", line 187, in _get_response
    response = self.process_exception_by_middleware(e, request)
  File "D:\Python27\lib\site-packages\django\core\handlers\base.py", line 185, in _get_response
    response = wrapped_callback(request, *callback_args, **callback_kwargs)
  File "D:\Python27\lib\site-packages\django\views\generic\base.py", line 68, in view
    return self.dispatch(request, *args, **kwargs)
  File "D:\Python27\lib\site-packages\django\views\generic\base.py", line 88, in dispatch
    return handler(request, *args, **kwargs)
  File "D:\MyPythonProject\MSS\StreamSystem\class_based_views.py", line 62, in post
    return self.json_response(reply)
  File "D:\MyPythonProject\MSS\StreamSystem\class_based_views.py", line 25, in json_response
    return HttpResponse(json.dumps(content))
  File "D:\Python27\lib\json\__init__.py", line 244, in dumps
    return _default_encoder.encode(obj)
  File "D:\Python27\lib\json\encoder.py", line 207, in encode
    chunks = self.iterencode(o, _one_shot=True)
  File "D:\Python27\lib\json\encoder.py", line 270, in iterencode
    return _iterencode(o, 0)
  File "D:\Python27\lib\json\encoder.py", line 184, in default
    raise TypeError(repr(o) + " is not JSON serializable")
TypeError: <StreamSystem.StreamFunc.StartStreamMixin object at 0x034D94F0> is not JSON serializable
[ERROR][2018-07-02 10:53:10,229][Thread-18:4952][task_id:django.request][exception.py:135][Internal Server Error: /stream/add/]
Traceback (most recent call last):
  File "D:\Python27\lib\site-packages\django\core\handlers\exception.py", line 41, in inner
    response = get_response(request)
  File "D:\Python27\lib\site-packages\django\core\handlers\base.py", line 187, in _get_response
    response = self.process_exception_by_middleware(e, request)
  File "D:\Python27\lib\site-packages\django\core\handlers\base.py", line 185, in _get_response
    response = wrapped_callback(request, *callback_args, **callback_kwargs)
  File "D:\Python27\lib\site-packages\django\views\generic\base.py", line 68, in view
    return self.dispatch(request, *args, **kwargs)
  File "D:\Python27\lib\site-packages\django\views\generic\base.py", line 88, in dispatch
    return handler(request, *args, **kwargs)
  File "D:\MyPythonProject\MSS\StreamSystem\class_based_views.py", line 62, in post
    return self.json_response(reply)
  File "D:\MyPythonProject\MSS\StreamSystem\class_based_views.py", line 25, in json_response
    return HttpResponse(json.dumps(content))
  File "D:\Python27\lib\json\__init__.py", line 244, in dumps
    return _default_encoder.encode(obj)
  File "D:\Python27\lib\json\encoder.py", line 207, in encode
    chunks = self.iterencode(o, _one_shot=True)
  File "D:\Python27\lib\json\encoder.py", line 270, in iterencode
    return _iterencode(o, 0)
  File "D:\Python27\lib\json\encoder.py", line 184, in default
    raise TypeError(repr(o) + " is not JSON serializable")
TypeError: <StreamSystem.StreamFunc.StartStreamMixin object at 0x038B8B70> is not JSON serializable
[ERROR][2018-07-02 11:00:35,732][Thread-1:10044][task_id:django.request][exception.py:135][Internal Server Error: /stream/add/]
Traceback (most recent call last):
  File "D:\Python27\lib\site-packages\django\core\handlers\exception.py", line 41, in inner
    response = get_response(request)
  File "D:\Python27\lib\site-packages\django\utils\deprecation.py", line 142, in __call__
    response = self.process_response(request, response)
  File "D:\Python27\lib\site-packages\django\middleware\clickjacking.py", line 32, in process_response
    if response.get('X-Frame-Options') is not None:
AttributeError: 'unicode' object has no attribute 'get'
[ERROR][2018-07-02 11:01:19,868][Thread-14:8352][task_id:django.request][exception.py:135][Internal Server Error: /stream/add/]
Traceback (most recent call last):
  File "D:\Python27\lib\site-packages\django\core\handlers\exception.py", line 41, in inner
    response = get_response(request)
  File "D:\Python27\lib\site-packages\django\utils\deprecation.py", line 142, in __call__
    response = self.process_response(request, response)
  File "D:\Python27\lib\site-packages\django\middleware\clickjacking.py", line 32, in process_response
    if response.get('X-Frame-Options') is not None:
AttributeError: 'unicode' object has no attribute 'get'
[ERROR][2018-07-02 11:05:24,161][Thread-1:6540][task_id:django.request][exception.py:135][Internal Server Error: /stream/add/]
Traceback (most recent call last):
  File "D:\Python27\lib\site-packages\django\core\handlers\exception.py", line 41, in inner
    response = get_response(request)
  File "D:\Python27\lib\site-packages\django\utils\deprecation.py", line 142, in __call__
    response = self.process_response(request, response)
  File "D:\Python27\lib\site-packages\django\middleware\common.py", line 115, in process_response
    if response.status_code == 404:
AttributeError: 'dict' object has no attribute 'status_code'
[ERROR][2018-07-02 11:07:36,233][Thread-8:8912][task_id:django.request][exception.py:135][Internal Server Error: /stream/add/]
Traceback (most recent call last):
  File "D:\Python27\lib\site-packages\django\core\handlers\exception.py", line 41, in inner
    response = get_response(request)
  File "D:\Python27\lib\site-packages\django\utils\deprecation.py", line 142, in __call__
    response = self.process_response(request, response)
  File "D:\Python27\lib\site-packages\django\middleware\common.py", line 115, in process_response
    if response.status_code == 404:
AttributeError: 'dict' object has no attribute 'status_code'
[ERROR][2018-07-04 10:11:16,848][Thread-6:8392][task_id:django.request][exception.py:135][Internal Server Error: /admin/djcelery/periodictask/]
Traceback (most recent call last):
  File "D:\Python27\lib\site-packages\django\core\handlers\exception.py", line 41, in inner
    response = get_response(request)
  File "D:\Python27\lib\site-packages\django\core\handlers\base.py", line 187, in _get_response
    response = self.process_exception_by_middleware(e, request)
  File "D:\Python27\lib\site-packages\django\core\handlers\base.py", line 185, in _get_response
    response = wrapped_callback(request, *callback_args, **callback_kwargs)
  File "D:\Python27\lib\site-packages\django\contrib\admin\options.py", line 551, in wrapper
    return self.admin_site.admin_view(view)(*args, **kwargs)
  File "D:\Python27\lib\site-packages\django\utils\decorators.py", line 149, in _wrapped_view
    response = view_func(request, *args, **kwargs)
  File "D:\Python27\lib\site-packages\django\views\decorators\cache.py", line 57, in _wrapped_view_func
    response = view_func(request, *args, **kwargs)
  File "D:\Python27\lib\site-packages\django\contrib\admin\sites.py", line 224, in inner
    return view(request, *args, **kwargs)
  File "D:\Python27\lib\site-packages\djcelery\admin.py", line 376, in changelist_view
    extra_context)
  File "D:\Python27\lib\site-packages\django\utils\decorators.py", line 67, in _wrapper
    return bound_func(*args, **kwargs)
  File "D:\Python27\lib\site-packages\django\utils\decorators.py", line 149, in _wrapped_view
    response = view_func(request, *args, **kwargs)
  File "D:\Python27\lib\site-packages\django\utils\decorators.py", line 63, in bound_func
    return func.__get__(self, type(self))(*args2, **kwargs2)
  File "D:\Python27\lib\site-packages\django\contrib\admin\options.py", line 1542, in changelist_view
    self.list_max_show_all, self.list_editable, self,
  File "D:\Python27\lib\site-packages\django\contrib\admin\views\main.py", line 79, in __init__
    self.get_results(request)
  File "D:\Python27\lib\site-packages\django\contrib\admin\views\main.py", line 177, in get_results
    result_count = paginator.count
  File "D:\Python27\lib\site-packages\django\utils\functional.py", line 35, in __get__
    res = instance.__dict__[self.name] = self.func(instance)
  File "D:\Python27\lib\site-packages\django\core\paginator.py", line 79, in count
    return self.object_list.count()
  File "D:\Python27\lib\site-packages\django\db\models\query.py", line 364, in count
    return self.query.get_count(using=self.db)
  File "D:\Python27\lib\site-packages\django\db\models\sql\query.py", line 499, in get_count
    number = obj.get_aggregation(using, ['__count'])['__count']
  File "D:\Python27\lib\site-packages\django\db\models\sql\query.py", line 480, in get_aggregation
    result = compiler.execute_sql(SINGLE)
  File "D:\Python27\lib\site-packages\django\db\models\sql\compiler.py", line 899, in execute_sql
    raise original_exception
OperationalError: no such table: djcelery_periodictask
[ERROR][2018-07-04 18:01:07,934][Thread-9:10832][task_id:django.request][exception.py:135][Internal Server Error: /get_log/]
Traceback (most recent call last):
  File "D:\Python27\lib\site-packages\django\core\handlers\exception.py", line 41, in inner
    response = get_response(request)
  File "D:\Python27\lib\site-packages\django\utils\deprecation.py", line 142, in __call__
    response = self.process_response(request, response)
  File "D:\Python27\lib\site-packages\django\middleware\clickjacking.py", line 32, in process_response
    if response.get('X-Frame-Options') is not None:
AttributeError: 'unicode' object has no attribute 'get'
[ERROR][2018-07-04 18:01:49,473][Thread-15:7748][task_id:django.request][exception.py:135][Internal Server Error: /get_log/]
Traceback (most recent call last):
  File "D:\Python27\lib\site-packages\django\core\handlers\exception.py", line 41, in inner
    response = get_response(request)
  File "D:\Python27\lib\site-packages\django\utils\deprecation.py", line 142, in __call__
    response = self.process_response(request, response)
  File "D:\Python27\lib\site-packages\django\middleware\clickjacking.py", line 32, in process_response
    if response.get('X-Frame-Options') is not None:
AttributeError: 'unicode' object has no attribute 'get'
[ERROR][2018-07-05 10:47:31,713][Thread-6:8868][task_id:django.request][exception.py:135][Internal Server Error: /get_log/]
Traceback (most recent call last):
  File "D:\Python27\lib\site-packages\django\core\handlers\exception.py", line 41, in inner
    response = get_response(request)
  File "D:\Python27\lib\site-packages\django\utils\deprecation.py", line 142, in __call__
    response = self.process_response(request, response)
  File "D:\Python27\lib\site-packages\django\middleware\clickjacking.py", line 32, in process_response
    if response.get('X-Frame-Options') is not None:
AttributeError: 'unicode' object has no attribute 'get'
[ERROR][2018-07-05 10:47:38,013][Thread-7:6036][task_id:django.request][exception.py:135][Internal Server Error: /get_log/]
Traceback (most recent call last):
  File "D:\Python27\lib\site-packages\django\core\handlers\exception.py", line 41, in inner
    response = get_response(request)
  File "D:\Python27\lib\site-packages\django\utils\deprecation.py", line 142, in __call__
    response = self.process_response(request, response)
  File "D:\Python27\lib\site-packages\django\middleware\clickjacking.py", line 32, in process_response
    if response.get('X-Frame-Options') is not None:
AttributeError: 'unicode' object has no attribute 'get'
